Watching for file changes with StatReloader
Performing system checks...

Return a fake base context to avoid connecting to third parties.
System check identified no issues (0 silenced).
February 04, 2021 - 23:52:33
Django version 3.0.1, using settings 'django_project.settings'
Starting ASGI/Channels version 3.0.2 development server at http://0.0.0.0:8000/
Quit the server with CONTROL-C.
Traceback (most recent call last):
  File "./manage.py", line 15, in <module>
    execute_from_command_line(sys.argv)
  File "/root/git/website/venv/lib/python3.7/site-packages/django/core/management/__init__.py", line 401, in execute_from_command_line
    utility.execute()
  File "/root/git/website/venv/lib/python3.7/site-packages/django/core/management/__init__.py", line 357, in execute
    autoreload.check_errors(django.setup)()
  File "/root/git/website/venv/lib/python3.7/site-packages/django/utils/autoreload.py", line 53, in wrapper
    fn(*args, **kwargs)
  File "/root/git/website/venv/lib/python3.7/site-packages/django/__init__.py", line 24, in setup
    apps.populate(settings.INSTALLED_APPS)
  File "/root/git/website/venv/lib/python3.7/site-packages/django/apps/registry.py", line 114, in populate
    app_config.import_models()
  File "/root/git/website/venv/lib/python3.7/site-packages/django/apps/config.py", line 211, in import_models
    self.models_module = import_module(models_module_name)
  File "/usr/lib/python3.7/importlib/__init__.py", line 127, in import_module
    return _bootstrap._gcd_import(name[level:], package, level)
  File "<frozen importlib._bootstrap>", line 1006, in _gcd_import
  File "<frozen importlib._bootstrap>", line 983, in _find_and_load
  File "<frozen importlib._bootstrap>", line 967, in _find_and_load_unlocked
  File "<frozen importlib._bootstrap>", line 677, in _load_unlocked
  File "<frozen importlib._bootstrap_external>", line 728, in exec_module
  File "<frozen importlib._bootstrap>", line 219, in _call_with_frames_removed
  File "/root/git/website/game/models.py", line 2, in <module>
    from django.contrib.auth.models import User
  File "/root/git/website/venv/lib/python3.7/site-packages/django/contrib/auth/models.py", line 2, in <module>
    from django.contrib.auth.base_user import AbstractBaseUser, BaseUserManager
  File "/root/git/website/venv/lib/python3.7/site-packages/django/contrib/auth/base_user.py", line 47, in <module>
    class AbstractBaseUser(models.Model):
  File "/root/git/website/venv/lib/python3.7/site-packages/django/db/models/base.py", line 121, in __new__
    new_class.add_to_class('_meta', Options(meta, app_label))
  File "/root/git/website/venv/lib/python3.7/site-packages/django/db/models/base.py", line 325, in add_to_class
    value.contribute_to_class(cls, name)
  File "/root/git/website/venv/lib/python3.7/site-packages/django/db/models/options.py", line 208, in contribute_to_class
    self.db_table = truncate_name(self.db_table, connection.ops.max_name_length())
  File "/root/git/website/venv/lib/python3.7/site-packages/django/db/__init__.py", line 28, in __getattr__
    return getattr(connections[DEFAULT_DB_ALIAS], item)
  File "/root/git/website/venv/lib/python3.7/site-packages/django/db/utils.py", line 207, in __getitem__
    backend = load_backend(db['ENGINE'])
  File "/root/git/website/venv/lib/python3.7/site-packages/django/db/utils.py", line 111, in load_backend
    return import_module('%s.base' % backend_name)
  File "/usr/lib/python3.7/importlib/__init__.py", line 127, in import_module
    return _bootstrap._gcd_import(name[level:], package, level)
  File "/root/git/website/venv/lib/python3.7/site-packages/django/db/backends/sqlite3/base.py", line 14, in <module>
    from sqlite3 import dbapi2 as Database
  File "/usr/lib/python3.7/sqlite3/__init__.py", line 23, in <module>
    from sqlite3.dbapi2 import *
  File "/usr/lib/python3.7/sqlite3/dbapi2.py", line 27, in <module>
    from _sqlite3 import *
KeyboardInterrupt
Traceback (most recent call last):
  File "./manage.py", line 15, in <module>
    execute_from_command_line(sys.argv)
  File "/root/git/website/venv/lib/python3.7/site-packages/django/core/management/__init__.py", line 401, in execute_from_command_line
    utility.execute()
  File "/root/git/website/venv/lib/python3.7/site-packages/django/core/management/__init__.py", line 357, in execute
    autoreload.check_errors(django.setup)()
  File "/root/git/website/venv/lib/python3.7/site-packages/django/utils/autoreload.py", line 53, in wrapper
    fn(*args, **kwargs)
  File "/root/git/website/venv/lib/python3.7/site-packages/django/__init__.py", line 24, in setup
    apps.populate(settings.INSTALLED_APPS)
  File "/root/git/website/venv/lib/python3.7/site-packages/django/apps/registry.py", line 91, in populate
    app_config = AppConfig.create(entry)
  File "/root/git/website/venv/lib/python3.7/site-packages/django/apps/config.py", line 116, in create
    mod = import_module(mod_path)
  File "/usr/lib/python3.7/importlib/__init__.py", line 127, in import_module
    return _bootstrap._gcd_import(name[level:], package, level)
  File "<frozen importlib._bootstrap>", line 1006, in _gcd_import
  File "<frozen importlib._bootstrap>", line 983, in _find_and_load
  File "<frozen importlib._bootstrap>", line 967, in _find_and_load_unlocked
  File "<frozen importlib._bootstrap>", line 677, in _load_unlocked
  File "<frozen importlib._bootstrap_external>", line 728, in exec_module
  File "<frozen importlib._bootstrap>", line 219, in _call_with_frames_removed
  File "/root/git/website/venv/lib/python3.7/site-packages/channels/apps.py", line 4, in <module>
    import daphne.server
  File "/root/git/website/venv/lib/python3.7/site-packages/daphne/server.py", line 5, in <module>
    from twisted.internet import asyncioreactor  # isort:skip
  File "/root/git/website/venv/lib/python3.7/site-packages/twisted/internet/asyncioreactor.py", line 17, in <module>
    from twisted.internet.posixbase import (PosixReactorBase, _NO_FILEDESC,
  File "/root/git/website/venv/lib/python3.7/site-packages/twisted/internet/posixbase.py", line 18, in <module>
    from twisted.internet import error, udp, tcp
  File "/root/git/website/venv/lib/python3.7/site-packages/twisted/internet/tcp.py", line 31, in <module>
    from twisted.internet._newtls import (
  File "/root/git/website/venv/lib/python3.7/site-packages/twisted/internet/_newtls.py", line 21, in <module>
    from twisted.protocols.tls import TLSMemoryBIOFactory, TLSMemoryBIOProtocol
  File "/root/git/website/venv/lib/python3.7/site-packages/twisted/protocols/tls.py", line 63, in <module>
    from twisted.internet._sslverify import _setAcceptableProtocols
  File "/root/git/website/venv/lib/python3.7/site-packages/twisted/internet/_sslverify.py", line 197, in <module>
    _selectVerifyImplementation()
  File "/root/git/website/venv/lib/python3.7/site-packages/twisted/internet/_sslverify.py", line 176, in _selectVerifyImplementation
    from service_identity import VerificationError
  File "/root/git/website/venv/lib/python3.7/site-packages/service_identity/__init__.py", line 7, in <module>
    from . import cryptography, pyopenssl
  File "/root/git/website/venv/lib/python3.7/site-packages/service_identity/pyopenssl.py", line 14, in <module>
    from pyasn1_modules.rfc2459 import GeneralNames
  File "/root/git/website/venv/lib/python3.7/site-packages/pyasn1_modules/rfc2459.py", line 725, in <module>
    class ORAddress(univ.Sequence):
  File "/root/git/website/venv/lib/python3.7/site-packages/pyasn1_modules/rfc2459.py", line 729, in ORAddress
    namedtype.OptionalNamedType('extension-attributes', ExtensionAttributes())
  File "/root/git/website/venv/lib/python3.7/site-packages/pyasn1/type/namedtype.py", line 161, in __init__
    self.__uniqueTagMap = self.__computeTagMaps(unique=True)
  File "/root/git/website/venv/lib/python3.7/site-packages/pyasn1/type/namedtype.py", line 484, in __computeTagMaps
    skipTypes.update(tagMap.skipTypes)
  File "/root/git/website/venv/lib/python3.7/site-packages/pyasn1/type/tagmap.py", line 77, in skipTypes
    @property
KeyboardInterrupt
Watching for file changes with StatReloader
HTTP GET /login/?next=/code/script/blank 200 [0.09, 127.0.0.1:54444]
Internal Server Error: /login/
Traceback (most recent call last):
  File "/root/git/website/venv/lib/python3.7/site-packages/django/core/handlers/exception.py", line 34, in inner
    response = get_response(request)
  File "/root/git/website/venv/lib/python3.7/site-packages/django/core/handlers/base.py", line 115, in _get_response
    response = self.process_exception_by_middleware(e, request)
  File "/root/git/website/venv/lib/python3.7/site-packages/django/core/handlers/base.py", line 113, in _get_response
    response = wrapped_callback(request, *callback_args, **callback_kwargs)
  File "/root/git/website/venv/lib/python3.7/site-packages/django/utils/decorators.py", line 130, in _wrapped_view
    response = view_func(request, *args, **kwargs)
  File "/root/git/website/users/views.py", line 74, in view
    login(request, user)
  File "/root/git/website/venv/lib/python3.7/site-packages/django/contrib/auth/__init__.py", line 125, in login
    request.session[SESSION_KEY] = user._meta.pk.value_to_string(user)
  File "/root/git/website/venv/lib/python3.7/site-packages/django/utils/functional.py", line 225, in inner
    return func(self._wrapped, *args)
AttributeError: 'AnonymousUser' object has no attribute '_meta'
HTTP POST /login/?next=/code/script/blank 500 [0.17, 127.0.0.1:54466]
HTTP GET /login/?next=/code/script/blank 200 [0.05, 127.0.0.1:54478]
Watching for file changes with StatReloader
Listen failure: Couldn't listen on 0.0.0.0:8000: [Errno 98] Address already in use.
Watching for file changes with StatReloader
HTTP GET /login/?next=/code/script/blank 200 [0.13, 127.0.0.1:54774]
Internal Server Error: /login/
Traceback (most recent call last):
  File "/root/git/website/venv/lib/python3.7/site-packages/django/core/handlers/exception.py", line 34, in inner
    response = get_response(request)
  File "/root/git/website/venv/lib/python3.7/site-packages/django/core/handlers/base.py", line 115, in _get_response
    response = self.process_exception_by_middleware(e, request)
  File "/root/git/website/venv/lib/python3.7/site-packages/django/core/handlers/base.py", line 113, in _get_response
    response = wrapped_callback(request, *callback_args, **callback_kwargs)
  File "/root/git/website/venv/lib/python3.7/site-packages/django/utils/decorators.py", line 130, in _wrapped_view
    response = view_func(request, *args, **kwargs)
  File "/root/git/website/users/views.py", line 74, in view
    login(request, user)
  File "/root/git/website/venv/lib/python3.7/site-packages/django/contrib/auth/__init__.py", line 125, in login
    request.session[SESSION_KEY] = user._meta.pk.value_to_string(user)
  File "/root/git/website/venv/lib/python3.7/site-packages/django/utils/functional.py", line 225, in inner
    return func(self._wrapped, *args)
AttributeError: 'AnonymousUser' object has no attribute '_meta'
HTTP POST /login/?next=/code/script/blank 500 [0.17, 127.0.0.1:54790]
Performing system checks...

Return a fake base context to avoid connecting to third parties.
System check identified no issues (0 silenced).
February 04, 2021 - 23:57:55
Django version 3.0.1, using settings 'django_project.settings'
Starting ASGI/Channels version 3.0.2 development server at http://0.0.0.0:8000/
Quit the server with CONTROL-C.
Performing system checks...

Return a fake base context to avoid connecting to third parties.
System check identified no issues (0 silenced).
February 05, 2021 - 00:02:30
Django version 3.0.1, using settings 'django_project.settings'
Starting ASGI/Channels version 3.0.2 development server at http://0.0.0.0:8000/
Quit the server with CONTROL-C.
Performing system checks...

Return a fake base context to avoid connecting to third parties.
System check identified no issues (0 silenced).
February 05, 2021 - 00:02:38
Django version 3.0.1, using settings 'django_project.settings'
Starting ASGI/Channels version 3.0.2 development server at http://0.0.0.0:8000/
Quit the server with CONTROL-C.
Performing system checks...

Return a fake base context to avoid connecting to third parties.
System check identified no issues (0 silenced).
February 05, 2021 - 00:02:49
Django version 3.0.1, using settings 'django_project.settings'
Starting ASGI/Channels version 3.0.2 development server at http://0.0.0.0:8000/
Quit the server with CONTROL-C.
Performing system checks...

Return a fake base context to avoid connecting to third parties.
System check identified no issues (0 silenced).
February 05, 2021 - 00:03:00
Django version 3.0.1, using settings 'django_project.settings'
Starting ASGI/Channels version 3.0.2 development server at http://0.0.0.0:8000/
Quit the server with CONTROL-C.
Traceback (most recent call last):
  File "/root/git/website/./manage.py", line 8, in <module>
    from django.core.management import execute_from_command_line
ModuleNotFoundError: No module named 'django'

The above exception was the direct cause of the following exception:

Traceback (most recent call last):
  File "/root/git/website/./manage.py", line 10, in <module>
    raise ImportError(
ImportError: Couldn't import Django. Are you sure it's installed and available on your PYTHONPATH environment variable? Did you forget to activate a virtual environment?
Watching for file changes with StatReloader
HTTP GET / 301 [0.00, 127.0.0.1:47434]
HTTP GET / 301 [0.00, 127.0.0.1:47436]
HTTP GET / 301 [0.00, 127.0.0.1:47438]
HTTP GET / 301 [0.00, 127.0.0.1:47440]
HTTP GET / 301 [0.00, 127.0.0.1:47442]
HTTP GET / 301 [0.00, 127.0.0.1:47444]
HTTP GET / 301 [0.00, 127.0.0.1:47446]
HTTP GET / 301 [0.00, 127.0.0.1:47448]
HTTP GET / 301 [0.00, 127.0.0.1:47450]
HTTP GET / 301 [0.00, 127.0.0.1:47452]
HTTP GET / 301 [0.00, 127.0.0.1:47454]
HTTP GET / 301 [0.00, 127.0.0.1:47456]
HTTP GET / 301 [0.00, 127.0.0.1:47458]
HTTP GET / 301 [0.00, 127.0.0.1:47460]
HTTP GET / 301 [0.00, 127.0.0.1:47462]
HTTP GET / 301 [0.00, 127.0.0.1:47464]
HTTP GET / 301 [0.00, 127.0.0.1:47466]
HTTP GET / 301 [0.00, 127.0.0.1:47468]
HTTP GET / 301 [0.00, 127.0.0.1:47470]
HTTP GET / 301 [0.00, 127.0.0.1:47474]
HTTP GET / 301 [0.00, 127.0.0.1:47478]
HTTP GET / 301 [0.00, 127.0.0.1:47480]
HTTP GET / 301 [0.00, 127.0.0.1:47482]
HTTP GET / 301 [0.00, 127.0.0.1:47484]
HTTP GET / 301 [0.00, 127.0.0.1:47486]
HTTP GET / 301 [0.00, 127.0.0.1:47488]
HTTP GET / 301 [0.00, 127.0.0.1:47490]
HTTP GET / 301 [0.00, 127.0.0.1:47492]
HTTP GET / 301 [0.00, 127.0.0.1:47494]
HTTP GET / 301 [0.00, 127.0.0.1:47496]
HTTP GET / 301 [0.00, 127.0.0.1:47498]
HTTP GET / 301 [0.00, 127.0.0.1:47500]
HTTP GET / 301 [0.00, 127.0.0.1:47502]
HTTP GET / 301 [0.00, 127.0.0.1:47504]
HTTP GET / 301 [0.00, 127.0.0.1:47506]
HTTP GET / 301 [0.00, 127.0.0.1:47508]
HTTP GET / 301 [0.00, 127.0.0.1:47510]
HTTP GET / 301 [0.00, 127.0.0.1:47512]
HTTP GET / 301 [0.00, 127.0.0.1:47514]
HTTP GET / 301 [0.00, 127.0.0.1:47516]
HTTP GET / 301 [0.00, 127.0.0.1:47532]
HTTP GET / 301 [0.00, 127.0.0.1:47534]
HTTP GET / 301 [0.00, 127.0.0.1:47536]
HTTP GET / 301 [0.00, 127.0.0.1:47538]
HTTP GET / 301 [0.00, 127.0.0.1:47540]
HTTP GET / 301 [0.00, 127.0.0.1:47542]
HTTP GET / 301 [0.00, 127.0.0.1:47544]
HTTP GET / 301 [0.00, 127.0.0.1:47548]
HTTP GET / 301 [0.00, 127.0.0.1:47550]
HTTP GET / 301 [0.00, 127.0.0.1:47552]
HTTP GET / 301 [0.00, 127.0.0.1:47554]
HTTP GET / 301 [0.00, 127.0.0.1:47556]
HTTP GET / 301 [0.00, 127.0.0.1:47558]
HTTP GET / 301 [0.00, 127.0.0.1:47560]
HTTP GET / 301 [0.00, 127.0.0.1:47562]
HTTP GET / 301 [0.00, 127.0.0.1:47564]
HTTP GET / 301 [0.00, 127.0.0.1:47566]
HTTP GET / 301 [0.00, 127.0.0.1:47568]
HTTP GET / 301 [0.00, 127.0.0.1:47570]
HTTP GET / 301 [0.00, 127.0.0.1:47572]
Performing system checks...

Return a fake base context to avoid connecting to third parties.
System check identified no issues (0 silenced).
February 05, 2021 - 01:45:26
Django version 3.0.1, using settings 'django_project.settings'
Starting ASGI/Channels version 3.0.2 development server at http://0.0.0.0:8000/
Quit the server with CONTROL-C.
Watching for file changes with StatReloader
Performing system checks...

Return a fake base context to avoid connecting to third parties.
System check identified no issues (0 silenced).
February 05, 2021 - 01:46:20
Django version 3.0.1, using settings 'django_project.settings'
Starting ASGI/Channels version 3.0.2 development server at http://0.0.0.0:8000/
Quit the server with CONTROL-C.
[2021-02-05 01:46:51 +0000] [138150] [INFO] Starting gunicorn 20.0.4
[2021-02-05 01:46:51 +0000] [138150] [INFO] Listening at: http://127.0.0.1:8000 (138150)
[2021-02-05 01:46:51 +0000] [138150] [INFO] Using worker: sync
[2021-02-05 01:46:51 +0000] [138153] [INFO] Booting worker with pid: 138153
[2021-02-05 01:46:51 +0000] [138153] [ERROR] Exception in worker process
Traceback (most recent call last):
  File "/root/git/website/venv/lib/python3.7/site-packages/gunicorn/arbiter.py", line 583, in spawn_worker
    worker.init_process()
  File "/root/git/website/venv/lib/python3.7/site-packages/gunicorn/workers/base.py", line 119, in init_process
    self.load_wsgi()
  File "/root/git/website/venv/lib/python3.7/site-packages/gunicorn/workers/base.py", line 144, in load_wsgi
    self.wsgi = self.app.wsgi()
  File "/root/git/website/venv/lib/python3.7/site-packages/gunicorn/app/base.py", line 67, in wsgi
    self.callable = self.load()
  File "/root/git/website/venv/lib/python3.7/site-packages/gunicorn/app/wsgiapp.py", line 49, in load
    return self.load_wsgiapp()
  File "/root/git/website/venv/lib/python3.7/site-packages/gunicorn/app/wsgiapp.py", line 39, in load_wsgiapp
    return util.import_app(self.app_uri)
  File "/root/git/website/venv/lib/python3.7/site-packages/gunicorn/util.py", line 358, in import_app
    mod = importlib.import_module(module)
  File "/usr/lib/python3.7/importlib/__init__.py", line 127, in import_module
    return _bootstrap._gcd_import(name[level:], package, level)
  File "<frozen importlib._bootstrap>", line 1006, in _gcd_import
  File "<frozen importlib._bootstrap>", line 983, in _find_and_load
  File "<frozen importlib._bootstrap>", line 965, in _find_and_load_unlocked
ModuleNotFoundError: No module named 'django_project/wsgi'
[2021-02-05 01:46:51 +0000] [138153] [INFO] Worker exiting (pid: 138153)
[2021-02-05 01:46:51 +0000] [138150] [INFO] Shutting down: Master
[2021-02-05 01:46:51 +0000] [138150] [INFO] Reason: Worker failed to boot.
[2021-02-05 01:47:36 +0000] [138645] [INFO] Starting gunicorn 20.0.4
[2021-02-05 01:47:36 +0000] [138645] [INFO] Listening at: http://127.0.0.1:8000 (138645)
[2021-02-05 01:47:36 +0000] [138645] [INFO] Using worker: sync
[2021-02-05 01:47:36 +0000] [138648] [INFO] Booting worker with pid: 138648
[2021-02-05 01:48:14 +0000] [138645] [INFO] Handling signal: int
[2021-02-05 01:48:14 +0000] [138648] [INFO] Worker exiting (pid: 138648)
[2021-02-05 01:48:14 +0000] [138645] [INFO] Shutting down: Master
